<?xml version="1.0"?>
<robot xmlns:xacro="http://www.ros.org/wiki/xacro" >

    <xacro:include filename="inertial_macros.xacro"/>


    <xacro:property name="chassis_length" value="0.299258"/>
    <xacro:property name="chassis_width" value="0.264"/>
    <xacro:property name="chassis_height" value="0.304902"/>
    <xacro:property name="chassis_mass" value="1.225156"/>
    <xacro:property name="arm_length" value="0.222788"/>
    <xacro:property name="arm_width" value="0.033"/>
    <xacro:property name="arm_height" value="0.111472"/>
    <xacro:property name="arm_mass" value="0.17912"/>
    <xacro:property name="wheel_radius" value="0.034"/>
    <xacro:property name="wheel_thickness" value="0.03085"/>
    <xacro:property name="wheel_mass" value="0.045987"/>


    <material name="grey">
        <color rgba="0.5 0.5 0.5 1"/>
    </material>

    <material name="red">
        <color rgba="1 0 0 1"/>
    </material>

    <!-- BASE LINK -->

    <link name ="base_link">

    </link>

    <!-- CHASSIS LINK -->

    <joint name="chassis_joint" type="fixed">
        <parent link="base_link"/>
        <child link="chassis"/>
        <origin xyz="0.046565 0 0.098366"/>
    </joint>

    <link name="chassis">
        <visual>
            <origin xyz="0 0 0"/>
            <geometry>
                <mesh filename="file:///home/shivam/rover_ws/src/rover_bot/description/meshes/chassis.stl"/>
            </geometry>
            <material name="grey"/>
        </visual>
        <collision>
            <origin xyz="-0.091666 0 0.028837"/>
            <geometry>
                <box size="${chassis_length} ${chassis_width} ${chassis_height}"/>
            </geometry>
        </collision>
        <!-- <xacro:inertial_box mass="${chassis_mass}" x="${chassis_length}" y="${chassis_width}" z="${chassis_height}">
            <origin xyz="-0.091666 0.0 0.028837" rpy="0 0 0"/>
        </xacro:inertial_box> -->
        <inertial>
            <mass value="1.225156"/>
            <inertia ixx="0.01117" ixy="0.000002132725" ixz="-0.0002573" iyx="0.000002132725" iyy="0.01053" iyz="0.000005544541" izx="-0.0002573" izy="0.000005544541" izz="0.01191"/>
            <origin xyz="-0.091666 0.0 0.028837" rpy="0 0 0"/>       
        </inertial>
    </link>
    <gazebo reference="chassis">
        <material>Gazebo/White</material>
    </gazebo>

    <!-- RIGHT ARM LINK -->

    <joint name="right_arm_joint" type="fixed">
        <parent link="chassis"/>
        <child link="right_arm"/>
        <origin xyz="0.034521 -0.100 -0.029025" />
    </joint>

    <link name="right_arm">
        <visual>
            <geometry>
                <mesh filename="file:///home/shivam/rover_ws/src/rover_bot/description/meshes/right_arm.stl"/>
            </geometry>
            <material name="grey"/>
        </visual>
        <collision>
            <origin xyz="0 -0.016946 -0.037256" rpy="0 0 0"/>
            <geometry>
                <box size="0.222788 0.033 0.111472"/>
            </geometry>
        </collision>
        <xacro:inertial_arm mass="${arm_mass}" >
            <origin xyz="0 -0.016946 -0.037256" rpy="0 0 0"/>
        </xacro:inertial_arm>
    </link>
    <gazebo reference="right_arm">
        <material>Gazebo/White</material>
    </gazebo>


    <!-- LEFT ARM LINK -->

    <joint name="left_arm_joint" type="fixed">
        <parent link="chassis"/>
        <child link="left_arm"/>
        <origin xyz="0.034521 0.100 -0.029025" rpy="0 0 ${pi}"/>
    </joint>

    <link name="left_arm">
        <visual>
            <geometry>
                <mesh filename="file:///home/shivam/rover_ws/src/rover_bot/description/meshes/left_arm.stl"/>
            </geometry>
            <material name="grey"/>
        </visual>
        <collision>
            <origin xyz="0 -0.016946 -0.037256" rpy="0 0 0"/> 
            <geometry>
                <box size="0.222788 0.033 0.111472"/>
            </geometry>
        </collision>
        <xacro:inertial_arm mass="${arm_mass}" >
            <origin xyz="0 -0.016946 -0.037256" rpy="0 0 0"/>
        </xacro:inertial_arm>
    </link>
    <gazebo reference="left_arm">
        <material>Gazebo/White</material>
    </gazebo>

    <!-- WHEELS -->
    <!-- RIGHT MIDDLE WHEEL LINK -->

    <joint name="right_middle_wheel_joint" type="continuous">
        <parent link="base_link"/>
        <child link="right_middle_wheel"/>
        <origin xyz="0 -0.133 0" rpy="${pi/2} 0 0"/>
        <axis xyz="0 0 -1"/>
    </joint>

    <link name="right_middle_wheel">
        <visual>
            <origin xyz="0 0 0" rpy="0 ${pi/2} 0"/>
            <geometry>
                <mesh filename="file:///home/shivam/rover_ws/src/rover_bot/description/meshes/wheel.stl"/>
            </geometry>
            <material name="grey"/>
        </visual>
        <collision>
            <origin xyz="0 0 0.016326" rpy="0 0 0"/>
            <geometry>
                <sphere radius="${wheel_radius}"/>
            </geometry>
        </collision>
        <xacro:inertial_cylinder mass="${wheel_mass}" length="${wheel_thickness}" radius="${wheel_radius}">
            <origin xyz="0 0 0.016326" rpy="0 0 0"/>
        </xacro:inertial_cylinder>

    </link>
    <gazebo reference="right_middle_wheel">
        <material>Gazebo/White</material>
    </gazebo>

    <!-- RIGHT REAR WHEEL LINK -->

    <joint name="right_rear_wheel_joint" type="continuous">
        <parent link="base_link"/>
        <child link="right_rear_wheel"/>
        <origin xyz="-0.165 -0.133 0" rpy="${pi/2} 0 0"/>
        <axis xyz="0 0 -1"/>
    </joint>

    <link name="right_rear_wheel">
        <visual>
            <origin xyz="0 0 0" rpy="0 ${pi/2} 0"/>
            <geometry>
                <mesh filename="file:///home/shivam/rover_ws/src/rover_bot/description/meshes/wheel.stl"/>
            </geometry>
            <material name="grey"/>
        </visual>
        <collision>
            <origin xyz="0 0 0.016326" rpy="0 0 0"/>
            <geometry>
                <sphere radius="${wheel_radius}"/>
            </geometry>
        </collision>
        <xacro:inertial_cylinder mass="${wheel_mass}" length="${wheel_thickness}" radius="${wheel_radius}">
            <origin xyz="0 0 0.016326" rpy="0 0 0"/>
        </xacro:inertial_cylinder>
    </link>
    <gazebo reference="right_middle_wheel">
        <material>Gazebo/White</material>
    </gazebo>

    <!-- RIGHT FRONT WHEEL LINK -->

    <joint name="right_front_wheel_joint" type="continuous">
        <parent link="base_link"/>
        <child link="right_front_wheel"/>
        <origin xyz="0.165 -0.133 0" rpy="${pi/2} 0 0"/>
        <axis xyz="0 0 -1"/>
    </joint>

    <link name="right_front_wheel">
        <visual>
            <origin xyz="0 0 0" rpy="0 ${pi/2} 0"/>
            <geometry>
                <mesh filename="file:///home/shivam/rover_ws/src/rover_bot/description/meshes/wheel.stl"/>
            </geometry>
            <material name="grey"/>
        </visual>
        <collision>
            <origin xyz="0 0 0.016326" rpy="0 0 0"/>
            <geometry>
                <sphere radius="${wheel_radius}"/>
            </geometry>
        </collision>
        <xacro:inertial_cylinder mass="${wheel_mass}" length="${wheel_thickness}" radius="${wheel_radius}">
            <origin xyz="0 0 0.016326" rpy="0 0 0"/>
        </xacro:inertial_cylinder>
    </link>
    <gazebo reference="right_middle_wheel">
        <material>Gazebo/White</material>
    </gazebo>

    <!-- LEFT MIDDLE WHEEL LINK -->

    <joint name="left_middle_wheel_joint" type="continuous">
        <parent link="base_link"/>
        <child link="left_middle_wheel"/>
        <origin xyz="0 0.133 0" rpy="${pi/2} 0 0"/>
        <axis xyz="0 0 -1"/>
    </joint>

    <link name="left_middle_wheel">
        <visual>
            <origin xyz="0 0 0" rpy="0 -${pi/2} 0"/>
            <geometry>
                <mesh filename="file:///home/shivam/rover_ws/src/rover_bot/description/meshes/wheel.stl"/>
            </geometry>
            <material name="grey"/>
        </visual>
        <collision>
            <origin xyz="0 0 -0.016326" rpy="0 0 0"/>
            <geometry>
                <sphere radius="${wheel_radius}"/>
            </geometry>
        </collision>
        <xacro:inertial_cylinder mass="${wheel_mass}" length="${wheel_thickness}" radius="${wheel_radius}">
            <origin xyz="0 0 -0.016326" rpy="0 0 0"/>
        </xacro:inertial_cylinder>
    </link>
    <gazebo reference="left_middle_wheel">
        <material>Gazebo/White</material>
    </gazebo>

    <!-- LEFT REAR WHEEL LINK -->

    <joint name="left_rear_wheel_joint" type="continuous">
        <parent link="base_link"/>
        <child link="left_rear_wheel"/>
        <origin xyz="-0.165 0.133 0" rpy="${pi/2} 0 0"/>
        <axis xyz="0 0 -1"/>
    </joint>

    <link name="left_rear_wheel">
        <visual>
            <origin xyz="0 0 0" rpy="0 -${pi/2} 0"/>
            <geometry>
                <mesh filename="file:///home/shivam/rover_ws/src/rover_bot/description/meshes/wheel.stl"/>
            </geometry>
            <material name="grey"/>
        </visual>
        <collision>
            <origin xyz="0 0 -0.016326" rpy="0 0 0"/>
            <geometry>
                <sphere radius="${wheel_radius}"/>
            </geometry>
        </collision>
        <xacro:inertial_cylinder mass="${wheel_mass}" length="${wheel_thickness}" radius="${wheel_radius}">
            <origin xyz="0 0 -0.016326" rpy="0 0 0"/>
        </xacro:inertial_cylinder>
    </link>
    <gazebo reference="left_rear_wheel_joint">
        <material>Gazebo/White</material>
    </gazebo>

    <!-- LEFT FRONT WHEEL LINK -->

    <joint name="left_front_wheel_joint" type="continuous">
        <parent link="base_link"/>
        <child link="left_front_wheel"/>
        <origin xyz="0.165 0.133 0" rpy="${pi/2} 0 0"/>
        <axis xyz="0 0 -1"/>
    </joint>

    <link name="left_front_wheel">
        <visual>
            <origin xyz="0 0 0" rpy="0 -${pi/2} 0"/>
            <geometry>
                <mesh filename="file:///home/shivam/rover_ws/src/rover_bot/description/meshes/wheel.stl"/>
            </geometry>
            <material name="grey"/>
        </visual>
        <collision>
            <origin xyz="0 0 -0.016326" rpy="0 0 0"/>
            <geometry>
                <sphere radius="${wheel_radius}"/>
            </geometry>
        </collision>
        <xacro:inertial_cylinder mass="${wheel_mass}" length="${wheel_thickness}" radius="${wheel_radius}">
            <origin xyz="0 0 -0.016326" rpy="0 0 0"/>
        </xacro:inertial_cylinder>
    </link>
    <gazebo reference="left_front_wheel_joint">
        <material>Gazebo/White</material>
    </gazebo>


</robot>